[2022-12-08T22:28:21.487+0000] {taskinstance.py:1087} INFO - Dependencies all met for <TaskInstance: back_in_avro.First_task_backup manual__2022-12-08T22:28:19.960165+00:00 [queued]>
[2022-12-08T22:28:21.514+0000] {taskinstance.py:1087} INFO - Dependencies all met for <TaskInstance: back_in_avro.First_task_backup manual__2022-12-08T22:28:19.960165+00:00 [queued]>
[2022-12-08T22:28:21.516+0000] {taskinstance.py:1283} INFO - 
--------------------------------------------------------------------------------
[2022-12-08T22:28:21.518+0000] {taskinstance.py:1284} INFO - Starting attempt 1 of 6
[2022-12-08T22:28:21.520+0000] {taskinstance.py:1285} INFO - 
--------------------------------------------------------------------------------
[2022-12-08T22:28:21.562+0000] {taskinstance.py:1304} INFO - Executing <Task(PythonOperator): First_task_backup> on 2022-12-08 22:28:19.960165+00:00
[2022-12-08T22:28:21.575+0000] {standard_task_runner.py:55} INFO - Started process 5967 to run task
[2022-12-08T22:28:21.582+0000] {standard_task_runner.py:82} INFO - Running: ['***', 'tasks', 'run', 'back_in_avro', 'First_task_backup', 'manual__2022-12-08T22:28:19.960165+00:00', '--job-id', '26', '--raw', '--subdir', 'DAGS_FOLDER/dag_back_in_avro.py', '--cfg-path', '/tmp/tmplrcb_wq3']
[2022-12-08T22:28:21.587+0000] {standard_task_runner.py:83} INFO - Job 26: Subtask First_task_backup
[2022-12-08T22:28:21.714+0000] {task_command.py:389} INFO - Running <TaskInstance: back_in_avro.First_task_backup manual__2022-12-08T22:28:19.960165+00:00 [running]> on host c4fdd5f7672d
[2022-12-08T22:28:21.869+0000] {taskinstance.py:1513} INFO - Exporting the following env vars:
AIRFLOW_CTX_DAG_OWNER=Martin_Jurado
AIRFLOW_CTX_DAG_ID=back_in_avro
AIRFLOW_CTX_TASK_ID=First_task_backup
AIRFLOW_CTX_EXECUTION_DATE=2022-12-08T22:28:19.960165+00:00
AIRFLOW_CTX_TRY_NUMBER=1
AIRFLOW_CTX_DAG_RUN_ID=manual__2022-12-08T22:28:19.960165+00:00
[2022-12-08T22:28:21.944+0000] {logging_mixin.py:137} INFO - There is information in the database
[2022-12-08T22:28:21.945+0000] {taskinstance.py:1772} ERROR - Task failed with exception
Traceback (most recent call last):
  File "/home/airflow/.local/lib/python3.7/site-packages/airflow/operators/python.py", line 175, in execute
    return_value = self.execute_callable()
  File "/home/airflow/.local/lib/python3.7/site-packages/airflow/operators/python.py", line 192, in execute_callable
    return self.python_callable(*self.op_args, **self.op_kwargs)
  File "/opt/airflow/dags/dag_back_in_avro.py", line 113, in jobs_back_up
    create_back_up()
  File "/opt/airflow/dags/dag_back_in_avro.py", line 59, in create_back_up
    schema_jobs_parsed = avro.schema.parse(json.dumps(schema_jobs))
NameError: name 'avro' is not defined
[2022-12-08T22:28:21.968+0000] {taskinstance.py:1327} INFO - Marking task as UP_FOR_RETRY. dag_id=back_in_avro, task_id=First_task_backup, execution_date=20221208T222819, start_date=20221208T222821, end_date=20221208T222821
[2022-12-08T22:28:21.997+0000] {standard_task_runner.py:105} ERROR - Failed to execute job 26 for task First_task_backup (name 'avro' is not defined; 5967)
[2022-12-08T22:28:22.040+0000] {local_task_job.py:159} INFO - Task exited with return code 1
[2022-12-08T22:28:22.078+0000] {taskinstance.py:2582} INFO - 0 downstream tasks scheduled from follow-on schedule check
