[2022-12-08T21:55:49.059+0000] {taskinstance.py:1087} INFO - Dependencies all met for <TaskInstance: back_in_avro.First_task_backup scheduled__2022-12-08T20:00:00+00:00 [queued]>
[2022-12-08T21:55:49.075+0000] {taskinstance.py:1087} INFO - Dependencies all met for <TaskInstance: back_in_avro.First_task_backup scheduled__2022-12-08T20:00:00+00:00 [queued]>
[2022-12-08T21:55:49.076+0000] {taskinstance.py:1283} INFO - 
--------------------------------------------------------------------------------
[2022-12-08T21:55:49.077+0000] {taskinstance.py:1284} INFO - Starting attempt 6 of 6
[2022-12-08T21:55:49.078+0000] {taskinstance.py:1285} INFO - 
--------------------------------------------------------------------------------
[2022-12-08T21:55:49.098+0000] {taskinstance.py:1304} INFO - Executing <Task(PythonOperator): First_task_backup> on 2022-12-08 20:00:00+00:00
[2022-12-08T21:55:49.107+0000] {standard_task_runner.py:55} INFO - Started process 3784 to run task
[2022-12-08T21:55:49.116+0000] {standard_task_runner.py:82} INFO - Running: ['***', 'tasks', 'run', 'back_in_avro', 'First_task_backup', 'scheduled__2022-12-08T20:00:00+00:00', '--job-id', '23', '--raw', '--subdir', 'DAGS_FOLDER/dag_back_in_avro.py', '--cfg-path', '/tmp/tmp5vq9ulyr']
[2022-12-08T21:55:49.120+0000] {standard_task_runner.py:83} INFO - Job 23: Subtask First_task_backup
[2022-12-08T21:55:49.196+0000] {task_command.py:389} INFO - Running <TaskInstance: back_in_avro.First_task_backup scheduled__2022-12-08T20:00:00+00:00 [running]> on host c4fdd5f7672d
[2022-12-08T21:55:49.279+0000] {taskinstance.py:1513} INFO - Exporting the following env vars:
AIRFLOW_CTX_DAG_OWNER=Martin_Jurado
AIRFLOW_CTX_DAG_ID=back_in_avro
AIRFLOW_CTX_TASK_ID=First_task_backup
AIRFLOW_CTX_EXECUTION_DATE=2022-12-08T20:00:00+00:00
AIRFLOW_CTX_TRY_NUMBER=6
AIRFLOW_CTX_DAG_RUN_ID=scheduled__2022-12-08T20:00:00+00:00
[2022-12-08T21:55:49.319+0000] {logging_mixin.py:137} INFO - There is not information in the database
[2022-12-08T21:55:49.320+0000] {logging_mixin.py:137} INFO - []
[2022-12-08T21:55:49.321+0000] {taskinstance.py:1772} ERROR - Task failed with exception
Traceback (most recent call last):
  File "/home/airflow/.local/lib/python3.7/site-packages/airflow/operators/python.py", line 175, in execute
    return_value = self.execute_callable()
  File "/home/airflow/.local/lib/python3.7/site-packages/airflow/operators/python.py", line 192, in execute_callable
    return self.python_callable(*self.op_args, **self.op_kwargs)
  File "/opt/airflow/dags/dag_back_in_avro.py", line 66, in jobs_back_up
    if n == 0:
UnboundLocalError: local variable 'n' referenced before assignment
[2022-12-08T21:55:49.335+0000] {taskinstance.py:1327} INFO - Marking task as FAILED. dag_id=back_in_avro, task_id=First_task_backup, execution_date=20221208T200000, start_date=20221208T215549, end_date=20221208T215549
[2022-12-08T21:55:49.348+0000] {standard_task_runner.py:105} ERROR - Failed to execute job 23 for task First_task_backup (local variable 'n' referenced before assignment; 3784)
[2022-12-08T21:55:49.366+0000] {local_task_job.py:159} INFO - Task exited with return code 1
[2022-12-08T21:55:49.389+0000] {taskinstance.py:2582} INFO - 0 downstream tasks scheduled from follow-on schedule check
