[2022-12-08T21:51:46.169+0000] {taskinstance.py:1087} INFO - Dependencies all met for <TaskInstance: back_in_avro.First_task_backup scheduled__2022-12-08T20:00:00+00:00 [queued]>
[2022-12-08T21:51:46.185+0000] {taskinstance.py:1087} INFO - Dependencies all met for <TaskInstance: back_in_avro.First_task_backup scheduled__2022-12-08T20:00:00+00:00 [queued]>
[2022-12-08T21:51:46.186+0000] {taskinstance.py:1283} INFO - 
--------------------------------------------------------------------------------
[2022-12-08T21:51:46.187+0000] {taskinstance.py:1284} INFO - Starting attempt 4 of 6
[2022-12-08T21:51:46.188+0000] {taskinstance.py:1285} INFO - 
--------------------------------------------------------------------------------
[2022-12-08T21:51:46.210+0000] {taskinstance.py:1304} INFO - Executing <Task(PythonOperator): First_task_backup> on 2022-12-08 20:00:00+00:00
[2022-12-08T21:51:46.220+0000] {standard_task_runner.py:55} INFO - Started process 3482 to run task
[2022-12-08T21:51:46.226+0000] {standard_task_runner.py:82} INFO - Running: ['***', 'tasks', 'run', 'back_in_avro', 'First_task_backup', 'scheduled__2022-12-08T20:00:00+00:00', '--job-id', '20', '--raw', '--subdir', 'DAGS_FOLDER/dag_back_in_avro.py', '--cfg-path', '/tmp/tmprzp_5ukp']
[2022-12-08T21:51:46.229+0000] {standard_task_runner.py:83} INFO - Job 20: Subtask First_task_backup
[2022-12-08T21:51:46.340+0000] {task_command.py:389} INFO - Running <TaskInstance: back_in_avro.First_task_backup scheduled__2022-12-08T20:00:00+00:00 [running]> on host c4fdd5f7672d
[2022-12-08T21:51:46.470+0000] {taskinstance.py:1513} INFO - Exporting the following env vars:
AIRFLOW_CTX_DAG_OWNER=Martin_Jurado
AIRFLOW_CTX_DAG_ID=back_in_avro
AIRFLOW_CTX_TASK_ID=First_task_backup
AIRFLOW_CTX_EXECUTION_DATE=2022-12-08T20:00:00+00:00
AIRFLOW_CTX_TRY_NUMBER=4
AIRFLOW_CTX_DAG_RUN_ID=scheduled__2022-12-08T20:00:00+00:00
[2022-12-08T21:51:46.518+0000] {logging_mixin.py:137} INFO - []
[2022-12-08T21:51:46.519+0000] {taskinstance.py:1772} ERROR - Task failed with exception
Traceback (most recent call last):
  File "/home/airflow/.local/lib/python3.7/site-packages/airflow/operators/python.py", line 175, in execute
    return_value = self.execute_callable()
  File "/home/airflow/.local/lib/python3.7/site-packages/airflow/operators/python.py", line 192, in execute_callable
    return self.python_callable(*self.op_args, **self.op_kwargs)
  File "/opt/airflow/dags/dag_back_in_avro.py", line 65, in jobs_back_up
    if n == 0:
UnboundLocalError: local variable 'n' referenced before assignment
[2022-12-08T21:51:46.544+0000] {taskinstance.py:1327} INFO - Marking task as UP_FOR_RETRY. dag_id=back_in_avro, task_id=First_task_backup, execution_date=20221208T200000, start_date=20221208T215146, end_date=20221208T215146
[2022-12-08T21:51:46.565+0000] {standard_task_runner.py:105} ERROR - Failed to execute job 20 for task First_task_backup (local variable 'n' referenced before assignment; 3482)
[2022-12-08T21:51:46.605+0000] {local_task_job.py:159} INFO - Task exited with return code 1
[2022-12-08T21:51:46.647+0000] {taskinstance.py:2582} INFO - 0 downstream tasks scheduled from follow-on schedule check
