[2022-12-08T20:54:56.194+0000] {taskinstance.py:1087} INFO - Dependencies all met for <TaskInstance: back_in_avro.First_task_backup scheduled__2022-12-08T19:00:00+00:00 [queued]>
[2022-12-08T20:54:56.214+0000] {taskinstance.py:1087} INFO - Dependencies all met for <TaskInstance: back_in_avro.First_task_backup scheduled__2022-12-08T19:00:00+00:00 [queued]>
[2022-12-08T20:54:56.216+0000] {taskinstance.py:1283} INFO - 
--------------------------------------------------------------------------------
[2022-12-08T20:54:56.217+0000] {taskinstance.py:1284} INFO - Starting attempt 1 of 6
[2022-12-08T20:54:56.218+0000] {taskinstance.py:1285} INFO - 
--------------------------------------------------------------------------------
[2022-12-08T20:54:56.241+0000] {taskinstance.py:1304} INFO - Executing <Task(PythonOperator): First_task_backup> on 2022-12-08 19:00:00+00:00
[2022-12-08T20:54:56.250+0000] {standard_task_runner.py:55} INFO - Started process 2922 to run task
[2022-12-08T20:54:56.256+0000] {standard_task_runner.py:82} INFO - Running: ['***', 'tasks', 'run', 'back_in_avro', 'First_task_backup', 'scheduled__2022-12-08T19:00:00+00:00', '--job-id', '5', '--raw', '--subdir', 'DAGS_FOLDER/dag_back_in_avro.py', '--cfg-path', '/tmp/tmp134f2ged']
[2022-12-08T20:54:56.259+0000] {standard_task_runner.py:83} INFO - Job 5: Subtask First_task_backup
[2022-12-08T20:54:56.354+0000] {task_command.py:389} INFO - Running <TaskInstance: back_in_avro.First_task_backup scheduled__2022-12-08T19:00:00+00:00 [running]> on host c4fdd5f7672d
[2022-12-08T20:54:56.462+0000] {taskinstance.py:1513} INFO - Exporting the following env vars:
AIRFLOW_CTX_DAG_OWNER=Martin_Jurado
AIRFLOW_CTX_DAG_ID=back_in_avro
AIRFLOW_CTX_TASK_ID=First_task_backup
AIRFLOW_CTX_EXECUTION_DATE=2022-12-08T19:00:00+00:00
AIRFLOW_CTX_TRY_NUMBER=1
AIRFLOW_CTX_DAG_RUN_ID=scheduled__2022-12-08T19:00:00+00:00
[2022-12-08T20:54:56.530+0000] {logging_mixin.py:137} INFO - Ingesta total
[2022-12-08T20:54:56.532+0000] {taskinstance.py:1772} ERROR - Task failed with exception
Traceback (most recent call last):
  File "/home/airflow/.local/lib/python3.7/site-packages/airflow/operators/python.py", line 175, in execute
    return_value = self.execute_callable()
  File "/home/airflow/.local/lib/python3.7/site-packages/airflow/operators/python.py", line 192, in execute_callable
    return self.python_callable(*self.op_args, **self.op_kwargs)
  File "/opt/airflow/dags/dag_back_in_avro.py", line 62, in jobs_back_up
    if n == True:
NameError: name 'n' is not defined
[2022-12-08T20:54:56.560+0000] {taskinstance.py:1327} INFO - Marking task as UP_FOR_RETRY. dag_id=back_in_avro, task_id=First_task_backup, execution_date=20221208T190000, start_date=20221208T205456, end_date=20221208T205456
[2022-12-08T20:54:56.585+0000] {standard_task_runner.py:105} ERROR - Failed to execute job 5 for task First_task_backup (name 'n' is not defined; 2922)
[2022-12-08T20:54:56.630+0000] {local_task_job.py:159} INFO - Task exited with return code 1
[2022-12-08T20:54:56.667+0000] {taskinstance.py:2582} INFO - 0 downstream tasks scheduled from follow-on schedule check
