[2022-12-08T21:35:55.177+0000] {taskinstance.py:1087} INFO - Dependencies all met for <TaskInstance: back_in_avro.First_task_backup scheduled__2022-12-08T19:00:00+00:00 [queued]>
[2022-12-08T21:35:56.333+0000] {taskinstance.py:1087} INFO - Dependencies all met for <TaskInstance: back_in_avro.First_task_backup scheduled__2022-12-08T19:00:00+00:00 [queued]>
[2022-12-08T21:35:56.341+0000] {taskinstance.py:1283} INFO - 
--------------------------------------------------------------------------------
[2022-12-08T21:35:56.363+0000] {taskinstance.py:1284} INFO - Starting attempt 3 of 6
[2022-12-08T21:35:56.368+0000] {taskinstance.py:1285} INFO - 
--------------------------------------------------------------------------------
[2022-12-08T21:35:56.776+0000] {taskinstance.py:1304} INFO - Executing <Task(PythonOperator): First_task_backup> on 2022-12-08 19:00:00+00:00
[2022-12-08T21:35:56.974+0000] {standard_task_runner.py:55} INFO - Started process 3130 to run task
[2022-12-08T21:35:57.002+0000] {standard_task_runner.py:82} INFO - Running: ['***', 'tasks', 'run', 'back_in_avro', 'First_task_backup', 'scheduled__2022-12-08T19:00:00+00:00', '--job-id', '12', '--raw', '--subdir', 'DAGS_FOLDER/dag_back_in_avro.py', '--cfg-path', '/tmp/tmp613b7yar']
[2022-12-08T21:35:57.034+0000] {standard_task_runner.py:83} INFO - Job 12: Subtask First_task_backup
[2022-12-08T21:35:57.352+0000] {task_command.py:389} INFO - Running <TaskInstance: back_in_avro.First_task_backup scheduled__2022-12-08T19:00:00+00:00 [running]> on host c4fdd5f7672d
[2022-12-08T21:35:57.651+0000] {taskinstance.py:1513} INFO - Exporting the following env vars:
AIRFLOW_CTX_DAG_OWNER=Martin_Jurado
AIRFLOW_CTX_DAG_ID=back_in_avro
AIRFLOW_CTX_TASK_ID=First_task_backup
AIRFLOW_CTX_EXECUTION_DATE=2022-12-08T19:00:00+00:00
AIRFLOW_CTX_TRY_NUMBER=3
AIRFLOW_CTX_DAG_RUN_ID=scheduled__2022-12-08T19:00:00+00:00
[2022-12-08T21:35:57.713+0000] {logging_mixin.py:137} INFO - Ingesta total
[2022-12-08T21:35:57.716+0000] {taskinstance.py:1772} ERROR - Task failed with exception
Traceback (most recent call last):
  File "/home/airflow/.local/lib/python3.7/site-packages/airflow/operators/python.py", line 175, in execute
    return_value = self.execute_callable()
  File "/home/airflow/.local/lib/python3.7/site-packages/airflow/operators/python.py", line 192, in execute_callable
    return self.python_callable(*self.op_args, **self.op_kwargs)
  File "/opt/airflow/dags/dag_back_in_avro.py", line 62, in jobs_back_up
    if n == True:
NameError: name 'n' is not defined
[2022-12-08T21:35:57.748+0000] {taskinstance.py:1327} INFO - Marking task as UP_FOR_RETRY. dag_id=back_in_avro, task_id=First_task_backup, execution_date=20221208T190000, start_date=20221208T213555, end_date=20221208T213557
[2022-12-08T21:35:57.780+0000] {standard_task_runner.py:105} ERROR - Failed to execute job 12 for task First_task_backup (name 'n' is not defined; 3130)
[2022-12-08T21:35:57.841+0000] {local_task_job.py:159} INFO - Task exited with return code 1
[2022-12-08T21:35:57.893+0000] {taskinstance.py:2582} INFO - 0 downstream tasks scheduled from follow-on schedule check
