[2022-12-08T21:51:46.191+0000] {taskinstance.py:1087} INFO - Dependencies all met for <TaskInstance: back_in_avro.First_task_backup manual__2022-12-08T20:54:59.992857+00:00 [queued]>
[2022-12-08T21:51:46.208+0000] {taskinstance.py:1087} INFO - Dependencies all met for <TaskInstance: back_in_avro.First_task_backup manual__2022-12-08T20:54:59.992857+00:00 [queued]>
[2022-12-08T21:51:46.209+0000] {taskinstance.py:1283} INFO - 
--------------------------------------------------------------------------------
[2022-12-08T21:51:46.210+0000] {taskinstance.py:1284} INFO - Starting attempt 6 of 6
[2022-12-08T21:51:46.211+0000] {taskinstance.py:1285} INFO - 
--------------------------------------------------------------------------------
[2022-12-08T21:51:46.231+0000] {taskinstance.py:1304} INFO - Executing <Task(PythonOperator): First_task_backup> on 2022-12-08 20:54:59.992857+00:00
[2022-12-08T21:51:46.240+0000] {standard_task_runner.py:55} INFO - Started process 3483 to run task
[2022-12-08T21:51:46.246+0000] {standard_task_runner.py:82} INFO - Running: ['***', 'tasks', 'run', 'back_in_avro', 'First_task_backup', 'manual__2022-12-08T20:54:59.992857+00:00', '--job-id', '21', '--raw', '--subdir', 'DAGS_FOLDER/dag_back_in_avro.py', '--cfg-path', '/tmp/tmpcpwovznp']
[2022-12-08T21:51:46.251+0000] {standard_task_runner.py:83} INFO - Job 21: Subtask First_task_backup
[2022-12-08T21:51:46.365+0000] {task_command.py:389} INFO - Running <TaskInstance: back_in_avro.First_task_backup manual__2022-12-08T20:54:59.992857+00:00 [running]> on host c4fdd5f7672d
[2022-12-08T21:51:46.485+0000] {taskinstance.py:1513} INFO - Exporting the following env vars:
AIRFLOW_CTX_DAG_OWNER=Martin_Jurado
AIRFLOW_CTX_DAG_ID=back_in_avro
AIRFLOW_CTX_TASK_ID=First_task_backup
AIRFLOW_CTX_EXECUTION_DATE=2022-12-08T20:54:59.992857+00:00
AIRFLOW_CTX_TRY_NUMBER=6
AIRFLOW_CTX_DAG_RUN_ID=manual__2022-12-08T20:54:59.992857+00:00
[2022-12-08T21:51:46.538+0000] {logging_mixin.py:137} INFO - []
[2022-12-08T21:51:46.539+0000] {taskinstance.py:1772} ERROR - Task failed with exception
Traceback (most recent call last):
  File "/home/airflow/.local/lib/python3.7/site-packages/airflow/operators/python.py", line 175, in execute
    return_value = self.execute_callable()
  File "/home/airflow/.local/lib/python3.7/site-packages/airflow/operators/python.py", line 192, in execute_callable
    return self.python_callable(*self.op_args, **self.op_kwargs)
  File "/opt/airflow/dags/dag_back_in_avro.py", line 65, in jobs_back_up
    if n == 0:
UnboundLocalError: local variable 'n' referenced before assignment
[2022-12-08T21:51:46.555+0000] {taskinstance.py:1327} INFO - Marking task as FAILED. dag_id=back_in_avro, task_id=First_task_backup, execution_date=20221208T205459, start_date=20221208T215146, end_date=20221208T215146
[2022-12-08T21:51:46.582+0000] {standard_task_runner.py:105} ERROR - Failed to execute job 21 for task First_task_backup (local variable 'n' referenced before assignment; 3483)
[2022-12-08T21:51:46.625+0000] {local_task_job.py:159} INFO - Task exited with return code 1
[2022-12-08T21:51:46.673+0000] {taskinstance.py:2582} INFO - 0 downstream tasks scheduled from follow-on schedule check
