[2022-12-08T21:49:44.591+0000] {taskinstance.py:1087} INFO - Dependencies all met for <TaskInstance: back_in_avro.First_task_backup manual__2022-12-08T20:54:59.992857+00:00 [queued]>
[2022-12-08T21:49:44.610+0000] {taskinstance.py:1087} INFO - Dependencies all met for <TaskInstance: back_in_avro.First_task_backup manual__2022-12-08T20:54:59.992857+00:00 [queued]>
[2022-12-08T21:49:44.612+0000] {taskinstance.py:1283} INFO - 
--------------------------------------------------------------------------------
[2022-12-08T21:49:44.613+0000] {taskinstance.py:1284} INFO - Starting attempt 5 of 6
[2022-12-08T21:49:44.614+0000] {taskinstance.py:1285} INFO - 
--------------------------------------------------------------------------------
[2022-12-08T21:49:44.651+0000] {taskinstance.py:1304} INFO - Executing <Task(PythonOperator): First_task_backup> on 2022-12-08 20:54:59.992857+00:00
[2022-12-08T21:49:44.669+0000] {standard_task_runner.py:55} INFO - Started process 3325 to run task
[2022-12-08T21:49:44.676+0000] {standard_task_runner.py:82} INFO - Running: ['***', 'tasks', 'run', 'back_in_avro', 'First_task_backup', 'manual__2022-12-08T20:54:59.992857+00:00', '--job-id', '17', '--raw', '--subdir', 'DAGS_FOLDER/dag_back_in_avro.py', '--cfg-path', '/tmp/tmpuj51wppp']
[2022-12-08T21:49:44.686+0000] {standard_task_runner.py:83} INFO - Job 17: Subtask First_task_backup
[2022-12-08T21:49:44.792+0000] {task_command.py:389} INFO - Running <TaskInstance: back_in_avro.First_task_backup manual__2022-12-08T20:54:59.992857+00:00 [running]> on host c4fdd5f7672d
[2022-12-08T21:49:44.897+0000] {taskinstance.py:1513} INFO - Exporting the following env vars:
AIRFLOW_CTX_DAG_OWNER=Martin_Jurado
AIRFLOW_CTX_DAG_ID=back_in_avro
AIRFLOW_CTX_TASK_ID=First_task_backup
AIRFLOW_CTX_EXECUTION_DATE=2022-12-08T20:54:59.992857+00:00
AIRFLOW_CTX_TRY_NUMBER=5
AIRFLOW_CTX_DAG_RUN_ID=manual__2022-12-08T20:54:59.992857+00:00
[2022-12-08T21:49:44.959+0000] {logging_mixin.py:137} INFO - Ingesta total
[2022-12-08T21:49:44.960+0000] {taskinstance.py:1772} ERROR - Task failed with exception
Traceback (most recent call last):
  File "/home/airflow/.local/lib/python3.7/site-packages/airflow/operators/python.py", line 175, in execute
    return_value = self.execute_callable()
  File "/home/airflow/.local/lib/python3.7/site-packages/airflow/operators/python.py", line 192, in execute_callable
    return self.python_callable(*self.op_args, **self.op_kwargs)
  File "/opt/airflow/dags/dag_back_in_avro.py", line 64, in jobs_back_up
    if n == 0:
NameError: name 'n' is not defined
[2022-12-08T21:49:44.978+0000] {taskinstance.py:1327} INFO - Marking task as UP_FOR_RETRY. dag_id=back_in_avro, task_id=First_task_backup, execution_date=20221208T205459, start_date=20221208T214944, end_date=20221208T214944
[2022-12-08T21:49:44.994+0000] {standard_task_runner.py:105} ERROR - Failed to execute job 17 for task First_task_backup (name 'n' is not defined; 3325)
[2022-12-08T21:49:45.018+0000] {local_task_job.py:159} INFO - Task exited with return code 1
[2022-12-08T21:49:45.048+0000] {taskinstance.py:2582} INFO - 0 downstream tasks scheduled from follow-on schedule check
